Workbook

Sheet 00_ReadMe
B1: RAHMAN ANIS & CO. • CHARTERED ACCOUNTANTS
B2: Statutory financial statements pack | Modern Pharmaceuticals Limited
B3: Year ended 30 June 2026 (comparative: 30 June 2025)
B5: KI KAJ KORA HOYECHE / WHAT THIS FILE IS
B6: Ei Excel ta Rahman Anis & Co.-er typical Bangladesh private-limited-company statutory audit financial statements format e toiri. Modern Pharmaceuticals Limited-er 30 June 2026 statutory audit-er jonno 2026 column (YELLOW / INK) khali rakha hoyeche — apni amount boshaben. 2025 column (BLUE) last year audited comparative-er jonno ready. IMPORTANT: Last year (YE 30 June 2025) audited PDF ei session-e attach/upload hoy nai. Tai 2025 figure ami guess/fake boshai nai. Apnar kache last year FS thakle BLUE cells-e audited 2025 amount boshan; 2026 YELLOW cells-e current year amount boshan. GREEN cells formula — type korben na. Last year PDF dile ami BLUE column-e audited figure boshiye updated file dite parbo.
B14: Sheet | C14: Ki ache | D14: Apni ki korben
B15: 00_ReadMe | C15: Ei instruction | D15: Porun
B16: 01_Cover | C16: Firm + client cover page | D16: Date / DVC / partner name
B17: 02_Contents | C17: Index of statements & notes | D17: Check
B18: 03_Auditors_Report | C18: ISA 700 + Companies Act 1994 report (draft) | D18: Opinion, KAMs if any, date, DVC, signature
B19: 04_SOFP | C19: Statement of Financial Position | D19: YELLOW 2026 amounts; BLUE 2025
B20: 05_SOPL | C20: Statement of Profit or Loss and OCI | D20: YELLOW 2026; BLUE 2025
B21: 06_SOCIE | C21: Statement of Changes in Equity | D21: Opening/dividend; PAT auto
B22: 07_SOCF | C22: Statement of Cash Flows (indirect) | D22: Working-capital & extra CF inks
B23: 08_Notes_Entity_Policies | C23: Notes 1–3: entity, basis, accounting policies | D23: Client-specific facts confirm
B24: 09_Notes_SOFP | C24: Notes 4–23: SOFP line notes | D24: Breakdowns — ink
B25: 10_Notes_P&L | C25: Notes 24–33: P&L notes + EPS | D25: Breakdowns — ink
... B31: 16_Balance_Check | C31: SOFP balance check + P&L to RE + CF tie | D31: Must be NIL difference
B33: HOW TO COMPLETE (5 steps)
B34: 1) 12_PPE_Schedule: 2025 opening (BLUE) last year PPE note theke; 2026 addition/disposal/charge YELLOW.
B35: 2) 13_COGS_Factory + 14_Admin_Selling + 15_Tax_WPPF: 2026 YELLOW, 2025 BLUE. Totals auto-jabe 05_SOPL / 10_Notes_P&L e.
B36: 3) 09_Notes_SOFP: baki SOFP breakdown (inventory, receivable, cash, loans, payables, share capital). Totals auto-jabe 04_SOFP e.
B37: 4) 06_SOCIE (dividend) + 07_SOCF extra inks (tax paid, capex, loan draw/repay). Check 16_Balance_Check = NIL.
B38: 5) 03_Auditors_Report e date, DVC, engagement partner; Cover print kore sign.
B40: FIRM / CLIENT (as used in this pack)
B41: Auditor | C41: Rahman Anis & Co., Chartered Accountants
B42: Head office | C42: Azad Center, Suit # 13/A-1, Floor-13, 55 Purana Paltan, Dhaka-1000
B43: Branch | C43: EDB Trade Center, 93 Kazi Nazrul Islam Avenue, Kawran Bazar, Dhaka-1215
B44: Email / phone | C44: info@rahmananis.com | +8801711-704808, +8801722-690128, +8801712-797042
B45: Client | C45: Modern Pharmaceuticals Limited
B46: Registered office (public listing) | C46: 51/51-A (3rd Floor), Purana Paltan, Dhaka-1000, Bangladesh
B47: Year end | C47: 30 June 2026 (comparative 30 June 2025)
B48: Framework | C48: IFRSs as adopted in Bangladesh; Companies Act 1994 (as amended); Income Tax Act 2023
B49: Currency | C49: Bangladeshi Taka (BDT) — amounts in Taka, no decimal unless noted
B52: Disclaimer: Ei pack ekta working / typing sheet. Last year audited figures chara comparative column incomplete. Opinion, DVC, KAMs, going-concern, subsequent events, related party o contingent disclosure engagement team confirm kore final korbe. Yellow/blue cells chhara green formula overwrite korben na.

Sheet 01_Cover
B5: RAHMAN ANIS & CO.
B6: CHARTERED ACCOUNTANTS
B7: Azad Center, Suit # 13/A-1, Floor-13, 55 Purana Paltan, Dhaka-1000, Bangladesh
B8: Tel: +8801711-704808 • info@rahmananis.com • www.rahmananis.com
B13: INDEPENDENT AUDITOR'S REPORT
B14: AND
B15: AUDITED FINANCIAL STATEMENTS
B18: MODERN PHARMACEUTICALS LIMITED
B19: For the year ended 30 June 2026
B22: Reporting entity | C22: Modern Pharmaceuticals Limited
B23: Financial year | C23: 1 July 2025 to 30 June 2026
B24: Comparative | C24: Year ended 30 June 2025 (last year audited)
B25: Framework | C25: IFRSs; Companies Act 1994 (as amended); Income Tax Act 2023
B26: Auditor | C26: Rahman Anis & Co., Chartered Accountants (Statutory auditor)
B27: Opinion type | C27: [Draft — unmodified / qualified — engagement partner to complete]
B28: Report date | C28: [ ]
B29: DVC | C29: [ ]
B30: Engagement partner | C30: [ ] FCA
B32: 2026 amounts: INK only (yellow cells throughout this workbook). 2025 amounts: last year audited balances — blue cells. Last year FS PDF was not provided in this working session; blue cells are left blank for insertion of audited 2025 figures.
B42: PRIVATE & CONFIDENTIAL • FOR THE SHAREHOLDERS AND THE BOARD OF DIRECTORS

Sheet 02_Contents
A1: RAHMAN ANIS & CO.
A2: Chartered Accountants
A4: Modern Pharmaceuticals Limited
A5: Audited Financial Statements
A6: For the year ended 30 June 2026
B9: Contents
B10: Description | C10: Sheet
B11: Independent Auditor's Report | C11: 03
B12: Statement of Financial Position | C12: 04
B13: Statement of Profit or Loss and Other Comprehensive Income | C13: 05
B14: Statement of Changes in Equity | C14: 06
B15: Statement of Cash Flows | C15: 07
B16: Notes to the Financial Statements | C16: 08–11
B17: Annexure A — Schedule of Property, Plant and Equipment | C17: 12
B18: Annexure B — Cost of Sales and Factory Overhead | C18: 13
B19: Annexure C — Administrative and Selling Expenses | C19: 14
B20: Annexure D — Tax and WPPF workings | C20: 15
B23: Notes index
B24: 1.00 Reporting entity | C24: 21.00 Liabilities for expenses
B25: 2.00 Basis of preparation | C25: 22.00 Provision for income tax
B26: 3.00 Significant accounting policies | C26: 23.00 Workers' Profit Participation Fund
B27: 4.00 Property, plant and equipment | C27: 24.00 Revenue
B28: 5.00 Capital work-in-progress | C28: 25.00 Cost of sales
B29: 6.00 Intangible assets | C29: 26.00 Other income
B30: 7.00 Right-of-use assets | C30: 27.00 Administrative expenses
B31: 8.00 Deferred tax (asset) / liability | C31: 28.00 Selling and distribution expenses
B32: 9.00 Inventories | C32: 29.00 Finance costs
B33: 10.00 Trade and other receivables | C33: 30.00 Finance income
B34: 11.00 Advances, deposits and prepayments | C34: 31.00 Contribution to WPPF
B35: 12.00 Advance income tax | C35: 32.00 Income tax expense
... B42: 19.00 Short-term borrowings | C42: 39.00 Authorisation of the financial statements
B43: 20.00 Current portion of long-term borrowings

Sheet 03_Auditors_Report
A1: RAHMAN ANIS & CO.
A2: Chartered Accountants
A4: Independent Auditor's Report
A5: To the Shareholders of Modern Pharmaceuticals Limited
A6: Report on the Audit of the Financial Statements
B9: Opinion
B10: We have audited the financial statements of Modern Pharmaceuticals Limited (the "Company"), which comprise the statement of financial position as at 30 June 2026, and the statement of profit or loss and other comprehensive income, statement of changes in equity and statement of cash flows for the year then ended, and notes to the financial statements, including a summary of significant accounting policies.
B11: In our opinion, the accompanying financial statements give a true and fair view of the financial position of the Company as at 30 June 2026, and of its financial performance and its cash flows for the year then ended in accordance with International Financial Reporting Standards (IFRSs) as adopted in Bangladesh and comply with the Companies Act 1994 (as amended to date) and other applicable laws and regulations.
B12: [DRAFT — Engagement partner: confirm unmodified / qualified / adverse / disclaimer. If modified, replace this paragraph and insert Basis for Qualified/Adverse Opinion. Yellow cells in the FS are incomplete until 2026 amounts are posted.]
B13: Basis for Opinion
B14: We conducted our audit in accordance with International Standards on Auditing (ISAs). Our responsibilities under those standards are further described in the Auditor's Responsibilities for the Audit of the Financial Statements section of our report. We are independent of the Company in accordance with the International Ethics Standards Board for Accountants' Code of Ethics for Professional Accountants (IESBA Code) together with the ethical requirements that are relevant to our audit of the financial statements in Bangladesh, and we have fulfilled our other ethical responsibilities in accordance with these requirements. We believe that the audit evidence we have obtained is sufficient and appropriate to provide a basis for our opinion.
B15: Other Information [if applicable]
B16: Management is responsible for the other information. The other information comprises the information included in the Annual Report / Directors' Report but does not include the financial statements and our auditor's report thereon. Our opinion on the financial statements does not cover the other information and we do not express any form of assurance conclusion thereon. [Complete or delete if no other information is obtained at the date of this report.]
B17: Responsibilities of Management and Those Charged with Governance for the Financial Statements
B18: Management is responsible for the preparation and fair presentation of the financial statements in accordance with IFRSs as adopted in Bangladesh and the Companies Act 1994 (as amended), and for such internal control as management determines is necessary to enable the preparation of financial statements that are free from material misstatement, whether due to fraud or error. In preparing the financial statements, management is responsible for assessing the Company's ability to continue as a going concern, disclosing, as applicable, matters related to going concern and using the going concern basis of accounting unless management either intends to liquidate the Company or to cease operations, or has no realistic alternative but to do so. Those charged with governance are responsible for overseeing the Company's financial reporting process.
B19: Auditor's Responsibilities for the Audit of the Financial Statements
B20: Our objectives are to obtain reasonable assurance about whether the financial statements as a whole are free from material misstatement, whether due to fraud or error, and to issue an auditor's report that includes our opinion. Reasonable assurance is a high level of assurance, but is not a guarantee that an audit conducted in accordance with ISAs will always detect a material misstatement when it exists. Misstatements can arise from fraud or error and are considered material if, individually or in the aggregate, they could reasonably be expected to influence the economic decisions of users taken on the basis of these financial statements.
... B35: DVC: ________________________

Sheet 04_SOFP
A1: RAHMAN ANIS & CO.
A2: Chartered Accountants
A4: Modern Pharmaceuticals Limited
A5: Statement of Financial Position
A6: As at 30 June 2026
A8: Colour key: YELLOW = 30 June 2026 INK (type amount) BLUE = 30 June 2025 last year audited comparative GREEN = auto formula (do not type)
A9: Particulars | B9: Notes | C9: 30 June 2026 Taka (INK — fill) | D9: 30 June 2025 Taka (Last year audited)
A10: ASSETS
A11: Non-current assets
A12: Property, plant and equipment | B12: 4.00 | C12: ='09_Notes_SOFP'!C11 | D12: ='09_Notes_SOFP'!D11
A13: Capital work-in-progress | B13: 5.00 | C13: ='09_Notes_SOFP'!C16 | D13: ='09_Notes_SOFP'!D16
A14: Intangible assets | B14: 6.00 | C14: ='09_Notes_SOFP'!C21 | D14: ='09_Notes_SOFP'!D21
A15: Right-of-use assets | B15: 7.00 | C15: ='09_Notes_SOFP'!C26 | D15: ='09_Notes_SOFP'!D26
A16: Investment in shares / others | B16: 13A | C16: ='09_Notes_SOFP'!C68 | D16: ='09_Notes_SOFP'!D68
A17: Other non-current assets | B17: 13A | C17: ='09_Notes_SOFP'!C69 | D17: ='09_Notes_SOFP'!D69
A18: Deferred tax asset (if DTL note is negative, present here — INK optional override) | C18: =IF('09_Notes_SOFP'!C28<0,-'09_Notes_SOFP'!C28,0) | D18: =IF('09_Notes_SOFP'!D28<0,-'09_Notes_SOFP'!D28,0)
A19: Total non-current assets | C19: =C12+C13+C14+C15+C16+C17+C18 | D19: =D12+D13+D14+D15+D16+D17+D18
A20: Current assets
A21: Inventories | B21: 9.00 | C21: ='09_Notes_SOFP'!C36 | D21: ='09_Notes_SOFP'!D36
A22: Trade and other receivables | B22: 10.00 | C22: ='09_Notes_SOFP'!C44 | D22: ='09_Notes_SOFP'!D44
A23: Advances, deposits and prepayments | B23: 11.00 | C23: ='09_Notes_SOFP'!C53 | D23: ='09_Notes_SOFP'!D53
A24: Advance income tax | B24: 12.00 | C24: ='09_Notes_SOFP'!C58 | D24: ='09_Notes_SOFP'!D58
A25: Short-term FDR / investments | B25: 13A | C25: ='09_Notes_SOFP'!C67 | D25: ='09_Notes_SOFP'!D67
A26: Cash and cash equivalents | B26: 13.00 | C26: ='09_Notes_SOFP'!C65 | D26: ='09_Notes_SOFP'!D65
A27: Total current assets | C27: =C21+C22+C23+C24+C25+C26 | D27: =D21+D22+D23+D24+D25+D26
A28: TOTAL ASSETS | C28: =C19+C27 | D28: =D19+D27
A30: EQUITY AND LIABILITIES
A31: Shareholders' equity
A32: Share capital | B32: 14.00 | C32: ='09_Notes_SOFP'!C72 | D32: ='09_Notes_SOFP'!D72
A33: Share premium | B33: 14.00 | C33: ='09_Notes_SOFP'!C73 | D33: ='09_Notes_SOFP'!D73
A34: Revaluation surplus | B34: 14.00 | C34: ='09_Notes_SOFP'!C74 | D34: ='09_Notes_SOFP'!D74
A35: Other reserve | B35: 14.00 | C35: ='09_Notes_SOFP'!C75 | D35: ='09_Notes_SOFP'!D75
A36: Retained earnings | B36: 15.00 | C36: ='09_Notes_SOFP'!C77 | D36: ='09_Notes_SOFP'!D77
A37: Total equity | C37: =C32+C33+C34+C35+C36 | D37: =D32+D33+D34+D35+D36
A38: Non-current liabilities
A39: Long-term borrowings | B39: 16.00 | C39: ='09_Notes_SOFP'!C81 | D39: ='09_Notes_SOFP'!D81
A40: Lease liabilities — non-current | B40: 17.00 | C40: ='09_Notes_SOFP'!C83 | D40: ='09_Notes_SOFP'!D83
A41: Deferred tax liability | B41: 8.00 | C41: =MAX('09_Notes_SOFP'!C28,0) | D41: =MAX('09_Notes_SOFP'!D28,0)
A42: Provision for gratuity — non-current | C42: ='09_Notes_SOFP'!C115 | D42: ='09_Notes_SOFP'!D115
A43: Other non-current liabilities | C43: ='09_Notes_SOFP'!C116 | D43: ='09_Notes_SOFP'!D116
...

Sheet 05_SOPL
A1: RAHMAN ANIS & CO.
A2: Chartered Accountants
A4: Modern Pharmaceuticals Limited
A5: Statement of Profit or Loss and Other Comprehensive Income
A6: For the year ended 30 June 2026
A8: Colour key: YELLOW = 30 June 2026 INK (type amount) BLUE = 30 June 2025 last year audited comparative GREEN = auto formula (do not type)
A9: Particulars | B9: Notes | C9: Year ended 30 June 2026 Taka (INK — fill) | D9: Year ended 30 June 2025 Taka (Last year audited)
A10: Revenue | B10: 24.00 | C10: ='10_Notes_PL'!C15 | D10: ='10_Notes_PL'!D15
A11: Cost of sales | B11: 25.00 | C11: ='10_Notes_PL'!C17 | D11: ='10_Notes_PL'!D17
A12: Gross profit | C12: =C10-C11 | D12: =D10-D11
A13: Other income | B13: 26.00 | C13: ='10_Notes_PL'!C23 | D13: ='10_Notes_PL'!D23
A14: Administrative expenses | B14: 27.00 | C14: ='10_Notes_PL'!C25 | D14: ='10_Notes_PL'!D25
A15: Selling and distribution expenses | B15: 28.00 | C15: ='10_Notes_PL'!C27 | D15: ='10_Notes_PL'!D27
A16: Operating profit | C16: =C12+C13-C14-C15 | D16: =D12+D13-D14-D15
A17: Finance costs | B17: 29.00 | C17: ='10_Notes_PL'!C34 | D17: ='10_Notes_PL'!D34
A18: Finance income | B18: 30.00 | C18: ='10_Notes_PL'!C36 | D18: ='10_Notes_PL'!D36
A19: Profit before WPPF and tax | C19: =C16-C17+C18 | D19: =D16-D17+D18
A20: Contribution to Workers' Profit Participation Fund | B20: 31.00 | C20: ='10_Notes_PL'!C38 | D20: ='10_Notes_PL'!D38
A21: Profit before tax | C21: =C19-C20 | D21: =D19-D20
A22: Income tax expense | B22: 32.00 | C22: ='10_Notes_PL'!C42 | D22: ='10_Notes_PL'!D42
A23: Profit for the year | C23: =C21-C22 | D23: =D21-D22
A25: Other comprehensive income
A26: Items that will not be reclassified to profit or loss (INK)
A27: Total comprehensive income for the year | C27: =C23+C26 | D27: =D23+D26
A29: Earnings per share
A30: Basic earnings per share (Taka) | B30: 33.00 | C30: ='10_Notes_PL'!C46 | D30: ='10_Notes_PL'!D46
A33: The annexed notes 1 to 39 form an integral part of these financial statements.
A35: ____________________________ | C35: ____________________________
A36: Director | C36: Director
A37: Modern Pharmaceuticals Limited
A39: Signed in terms of our separate report of even date.
A41: Dhaka | C41: Rahman Anis & Co.
A42: Dated: ________________ | C42: Chartered Accountants
C43: DVC: ________________________

Sheet 06_SOCIE
A1: RAHMAN ANIS & CO.
A2: Chartered Accountants
A4: Modern Pharmaceuticals Limited
A5: Statement of Changes in Equity
A6: For the year ended 30 June 2026
A8: Colour key: YELLOW = 30 June 2026 INK (type amount) BLUE = 30 June 2025 last year audited comparative GREEN = auto formula (do not type)
A9: Particulars | B9: Share capital | C9: Share premium | D9: Revaluation / other reserve | E9: Retained earnings | F9: Total equity
A10: Balance as at 01 July 2024 (opening of last year) — INK/BLUE from 2024 FS if needed | F10: =SUM(B10:E10)
A11: Profit for the year ended 30 June 2025 (last year PAT) | B11: 0 | C11: 0 | D11: 0 | E11: =05_SOPL!D23 | F11: =SUM(B11:E11)
A12: Other comprehensive income — year ended 30 June 2025 | E12: =05_SOPL!D26 | F12: =SUM(B12:E12)
A13: Dividend paid / issued during year ended 30 June 2025 (enter as negative) | F13: =SUM(B13:E13)
A14: Balance as at 30 June 2025 (last year audited) — equity face | B14: ='09_Notes_SOFP'!D72 | C14: ='09_Notes_SOFP'!D73 | D14: ='09_Notes_SOFP'!D74+'09_Notes_SOFP'!D75 | E14: ='09_Notes_SOFP'!D77 | F14: =SUM(B14:E14)
A16: Balance as at 01 July 2025 | B16: =B14 | C16: =C14 | D16: =D14 | E16: =E14 | F16: =F14
A17: Profit for the year ended 30 June 2026 | B17: 0 | C17: 0 | D17: 0 | E17: =05_SOPL!C23 | F17: =SUM(B17:E17)
A18: Other comprehensive income — year ended 30 June 2026 | E18: =05_SOPL!C26 | F18: =SUM(B18:E18)
A19: Issue of share capital during the year (INK) | F19: =SUM(B19:E19)
A20: Dividend declared / paid during year ended 30 June 2026 (enter as negative) | F20: =SUM(B20:E20)
A21: Balance as at 30 June 2026 | B21: =B16+B17+B18+B19+B20 | C21: =C16+C17+C18+C19+C20 | D21: =D16+D17+D18+D19+D20 | E21: =E16+E17+E18+E19+E20 | F21: =SUM(B21:E21)
A23: Tie-out vs Notes 14 / 15 (difference must be NIL)
A24: Share capital per SOCIE (30 June 2026) vs Note 14 paid-up | E24: =B21-'09_Notes_SOFP'!C72
A25: Share capital per SOCIE (30 June 2025) vs Note 14 paid-up LY | E25: =B14-'09_Notes_SOFP'!D72
A26: Share premium SOCIE CY vs Note | E26: =C21-'09_Notes_SOFP'!C73
A28: Suggested: put last year audited equity opening in row 10, and last year closing will compute in row 14.
A29: The annexed notes 1 to 39 form an integral part of these financial statements.
A31: ____________________________ | C31: ____________________________
A32: Director | C32: Director
A33: Modern Pharmaceuticals Limited
A35: Signed in terms of our separate report of even date.
A37: Dhaka | C37: Rahman Anis & Co.
A38: Dated: ________________ | C38: Chartered Accountants
C39: DVC: ________________________

Sheet 07_SOCF
A1: RAHMAN ANIS & CO.
A2: Chartered Accountants
A4: Modern Pharmaceuticals Limited
A5: Statement of Cash Flows
A6: For the year ended 30 June 2026
A8: Colour key: YELLOW = 30 June 2026 INK (type amount) BLUE = 30 June 2025 last year audited comparative GREEN = auto formula (do not type)
A9: Particulars | B9: Notes | C9: Year ended 30 June 2026 Taka | D9: Year ended 30 June 2025 Taka
A10: A. Cash flows from operating activities
A11: Profit before tax | C11: =05_SOPL!C21 | D11: =05_SOPL!D21
A12: Adjustments for:
A13: Depreciation of PPE | C13: ='12_PPE_Schedule'!J20
A14: Amortisation of intangibles | C14: ='09_Notes_SOFP'!C20 | D14: ='09_Notes_SOFP'!D20
A15: Depreciation of ROU assets | C15: ='09_Notes_SOFP'!C25 | D15: ='09_Notes_SOFP'!D25
A16: Finance costs | C16: =05_SOPL!C17 | D16: =05_SOPL!D17
A17: Finance / interest income | C17: =-(05_SOPL!C18+'10_Notes_PL'!C19) | D17: =-(05_SOPL!D18+'10_Notes_PL'!D19)
A18: (Gain) / loss on disposal of PPE | C18: =-'12_PPE_Schedule'!C50
A19: WPPF charged | C19: =05_SOPL!C20 | D19: =05_SOPL!D20
A20: Operating profit before working capital changes | C20: =C11+C13+C14+C15+C16+C17+C18+C19 | D20: =D11+D13+D14+D15+D16+D17+D18+D19
A21: Changes in working capital:
A22: (Increase) / decrease in inventories | C22: =04_SOFP!D21-04_SOFP!C21
A23: (Increase) / decrease in trade and other receivables | C23: =04_SOFP!D22-04_SOFP!C22
A24: (Increase) / decrease in advances, deposits and prepayments | C24: =04_SOFP!D23-04_SOFP!C23
A25: Increase / (decrease) in trade and other payables | C25: =04_SOFP!C46-04_SOFP!D46
A26: Increase / (decrease) in liabilities for expenses | C26: =04_SOFP!C50-04_SOFP!D50
A27: Cash generated from operations | C27: =C20+C22+C23+C24+C25+C26 | D27: =D20+D22+D23+D24+D25+D26
A28: Income tax paid (INK — typically AIT + payments)
A29: Interest paid (INK)
A30: WPPF paid (auto from Annexure D) | C30: =-'15_Tax_WPPF'!C46 | D30: =-'15_Tax_WPPF'!D46
A31: Net cash from / (used in) operating activities | C31: =C27-C28-C29+C30 | D31: =D27-D28-D29+D30
A33: B. Cash flows from investing activities
A34: Acquisition of PPE (INK — additions excluding CWIP transfer) | C34: =-'12_PPE_Schedule'!J13
A35: Capital work-in-progress addition (auto) | C35: =-'09_Notes_SOFP'!C14 | D35: =-'09_Notes_SOFP'!D14
A36: Acquisition of intangibles (auto) | C36: =-'09_Notes_SOFP'!C19 | D36: =-'09_Notes_SOFP'!D19
A37: Proceeds from sale of PPE (auto) | C37: ='12_PPE_Schedule'!C48
A38: Interest received (INK)
A39: (Increase) / decrease in FDR / investments (INK)
A40: Net cash from / (used in) investing activities | C40: =C34+C35+C36+C37+C38+C39 | D40: =D34+D35+D36+D37+D38+D39
A42: C. Cash flows from financing activities
A43: Proceeds from / (repayment of) long-term borrowings (INK)
A44: Proceeds from / (repayment of) short-term borrowings (auto SOFP movement) | C44: =04_SOFP!C47-04_SOFP!D47
...

Sheet 08_Notes_Policies
A1: RAHMAN ANIS & CO.
A2: Chartered Accountants
A4: Modern Pharmaceuticals Limited
A5: Notes to the financial statements
A6: For the year ended 30 June 2026
B9: 1.00 Reporting entity
B10: Modern Pharmaceuticals Limited (the "Company") is a private limited company incorporated in Bangladesh under the Companies Act 1994 (as amended). The registered office of the Company is at 51/51-A (3rd Floor), Purana Paltan, Dhaka-1000, Bangladesh [confirm from RJSC Form X / Memorandum]. The principal activities of the Company comprise manufacturing, marketing and sale of pharmaceutical finished products and/or related trading of pharmaceutical raw and packing materials in Bangladesh [confirm actual licence: DGDA manufacturing licence / depot]. These financial statements relate to the Company as a separate legal entity (no subsidiaries identified at the date of this draft).
B11: 1.01 Nature of business
B12: The Company is engaged in the pharmaceutical sector. Revenue arises primarily from sale of goods. DGDA, VAT and drug-pricing regulations apply. Confirm product mix (human / veterinary / API trading) before finalising this note.
B13: 2.00 Basis of preparation
B14: 2.01 Statement of compliance
B15: The financial statements have been prepared in accordance with International Financial Reporting Standards (IFRSs) as adopted in Bangladesh, the Companies Act 1994 (as amended to date), the Income Tax Act 2023, the Value Added Tax and Supplementary Duty Act 2012 and other applicable laws and regulations. The financial reporting framework is also informed by the Financial Reporting Act 2015 and directives of the Financial Reporting Council (FRC), Bangladesh, where applicable.
B16: 2.02 Other regulatory compliance
B17: The Company is also required to comply with: (i) The Bangladesh Labour Act 2006 (as amended) including Workers' Profit Participation Fund; (ii) DGDA rules and conditions of drug manufacturing / sales licences; (iii) The Securities and Exchange Rules only if listed (not assumed). Confirm listing status — this pack is drafted for an unlisted private limited company.
B18: 2.03 Basis of measurement
B19: The financial statements have been prepared on the historical cost basis except for certain items of property, plant and equipment that may be carried at revalued amount if a revaluation model is adopted, and except for financial instruments measured at fair value where applicable. The financial statements are prepared on an accrual basis.
B20: 2.04 Functional and presentation currency
... B70: If this is the first year of appointment of Rahman Anis & Co. as statutory auditor, opening balances have been considered in accordance with ISA 510. Comparative figures are those reported by the predecessor auditor [name of last year auditor — insert] for the year ended 30 June 2025.

Sheet 09_Notes_SOFP
A1: RAHMAN ANIS & CO.
A2: Chartered Accountants
A4: Modern Pharmaceuticals Limited
A5: Notes to the financial statements (Notes 4–23)
A6: As at 30 June 2026
A8: Colour key: YELLOW = 30 June 2026 INK (type amount) BLUE = 30 June 2025 last year audited comparative GREEN = auto formula (do not type)
A9: Particulars | B9: Notes | C9: 30 June 2026 Taka (INK — fill) | D9: 30 June 2025 Taka (Last year audited)
A10: 4.00 Property, plant and equipment
A11: Written down value (from Annexure A) | B11: 4.00 | C11: ='12_PPE_Schedule'!J25 | D11: ='12_PPE_Schedule'!J26
A12: 5.00 Capital work-in-progress
A13: Opening balance
A14: Add: Addition during the year
A15: Less: Transfer to PPE (should equal PPE row 14 total)
A16: Closing capital work-in-progress | C16: =C13+C14-C15 | D16: =D13+D14-D15
A17: 6.00 Intangible assets (software, product licences)
A18: Opening written down value
A19: Add: Addition
A20: Less: Amortisation for the year
A21: Closing intangible assets | B21: 6.00 | C21: =C18+C19-C20 | D21: =D18+D19-D20
A22: 7.00 Right-of-use assets (IFRS 16)
A23: Opening WDV of ROU assets
A24: Add: New leases
A25: Less: Depreciation of ROU assets
A26: Closing right-of-use assets | B26: 7.00 | C26: =C23+C24-C25 | D26: =D23+D24-D25
A27: 8.00 Deferred tax (asset) / liability
A28: Deferred tax liability / (asset) (from Annexure D) | B28: 8.00 | C28: ='15_Tax_WPPF'!C34 | D28: ='15_Tax_WPPF'!D34
A29: 9.00 Inventories (IAS 2 — lower of cost and NRV)
A30: Raw materials | B30: 9.01
A31: Packing materials | B31: 9.02
A32: Work-in-process | B32: 9.03
A33: Finished goods | B33: 9.04
A34: Spares, stores and others | B34: 9.05
A35: Less: Provision for slow-moving / obsolete stock (enter as positive)
A36: Total inventories | B36: 9.00 | C36: =C30+C31+C32+C33+C34-C35 | D36: =D30+D31+D32+D33+D34-D35
A37: Check vs COGS closing stocks (RM+PK+WIP+FG) — difference should be NIL if same figures used
A38: COGS closing RM+PK+WIP+FG (auto) | C38: ='13_COGS_Factory'!C14+'13_COGS_Factory'!C20+'13_COGS_Factory'!C42+'13_COGS_Factory'!C48 | D38: ='13_COGS_Factory'!D14+'13_COGS_Factory'!D20+'13_COGS_Factory'!D42+'13_COGS_Factory'!D48
A39: 10.00 Trade and other receivables
A40: Trade receivables — local
A41: Trade receivables — export
A42: Other receivables
...

Sheet 10_Notes_PL
A1: RAHMAN ANIS & CO.
A2: Chartered Accountants
A4: Modern Pharmaceuticals Limited
A5: Notes to the financial statements (Notes 24–33)
A6: For the year ended 30 June 2026
A8: Colour key: YELLOW = 30 June 2026 INK (type amount) BLUE = 30 June 2025 last year audited comparative GREEN = auto formula (do not type)
A9: Particulars | B9: Notes | C9: 30 June 2026 Taka (INK — fill) | D9: 30 June 2025 Taka (Last year audited)
A10: 24.00 Revenue (IFRS 15)
A11: Local sales of pharmaceutical products (gross)
A12: Export sales (gross)
A13: Less: VAT / SD included in gross (if sales are tax-inclusive) — enter positive
A14: Less: Sales return, rebate, discount — enter positive
A15: Net revenue | B15: 24.00 | C15: =C11+C12-C13-C14 | D15: =D11+D12-D13-D14
A16: 25.00 Cost of sales
A17: Cost of sales (from Annexure B) | B17: 25.00 | C17: ='13_COGS_Factory'!C49 | D17: ='13_COGS_Factory'!D49
A18: 26.00 Other income
A19: Interest on SND / FDR
A20: Gain on disposal of PPE (from PPE C50) / other | C20: ='12_PPE_Schedule'!C50
A21: Scrap / miscellaneous income
A22: Wastage / other operating income
A23: Total other income | B23: 26.00 | C23: =C19+C20+C21+C22 | D23: =D19+D20+D21+D22
A24: 27.00 Administrative expenses
A25: Administrative expenses (from Annexure C) | B25: 27.00 | C25: ='14_Admin_Selling'!C34 | D25: ='14_Admin_Selling'!D34
A26: 28.00 Selling and distribution expenses
A27: Selling and distribution expenses (from Annexure C) | B27: 28.00 | C27: ='14_Admin_Selling'!C53 | D27: ='14_Admin_Selling'!D53
A28: 29.00 Finance costs
A29: Interest on long-term borrowings
A30: Interest on short-term borrowings / CC / LTR
A31: Interest on lease liabilities (IFRS 16)
A32: Bank charges and commission (finance)
A33: Foreign exchange loss (if any)
A34: Total finance costs | B34: 29.00 | C34: =C29+C30+C31+C32+C33 | D34: =D29+D30+D31+D32+D33
A35: 30.00 Finance income
A36: Interest income (if classified as finance income rather than other income) | B36: 30.00
A37: 31.00 Contribution to WPPF
A38: WPPF (from Annexure D) | B38: 31.00 | C38: ='15_Tax_WPPF'!C14 | D38: ='15_Tax_WPPF'!D14
A39: 32.00 Income tax expense
A40: Current tax (from Annexure D) | C40: ='15_Tax_WPPF'!C25 | D40: ='15_Tax_WPPF'!D25
A41: Deferred tax expense / (income) (from Annexure D) | C41: ='15_Tax_WPPF'!C35 | D41: ='15_Tax_WPPF'!D35
A42: Total income tax expense | B42: 32.00 | C42: =C40+C41 | D42: =D40+D41
...

Sheet 11_Notes_Other
A1: RAHMAN ANIS & CO.
A2: Chartered Accountants
A4: Modern Pharmaceuticals Limited
A5: Notes to the financial statements (Notes 34–39)
A6: For the year ended 30 June 2026
A8: Colour key: YELLOW = 30 June 2026 INK (type amount) BLUE = 30 June 2025 last year audited comparative GREEN = auto formula (do not type)
A9: Particulars | B9: Notes | C9: 30 June 2026 Taka (INK — fill) | D9: 30 June 2025 Taka (Last year audited) | E9: Remarks / name of party
A10: 34.00 Related party disclosures (IAS 24)
A11: Name of related party / nature of relationship (INK names in col E)
A12: Directors' remuneration (also in admin)
A13: Sale of goods to related party
A14: Purchase of goods / services from related party
A15: Loan to / (from) related party — movement / closing
A16: Guarantee given to / received from related party
A17: Key management personnel compensation (other)
A18: Other related party transaction
A20: 35.00 Contingent liabilities and commitments
A21: Bank guarantee outstanding
A22: L/C (documentary credit) outstanding
... A45: These financial statements were authorised for issue by the Board of Directors of Modern Pharmaceuticals Limited on ____________________. Company Secretary / CFO to confirm minutes reference.

Sheet 12_PPE_Schedule
A1: RAHMAN ANIS & CO.
A2: Chartered Accountants
A4: Modern Pharmaceuticals Limited
A5: Annexure A — Schedule of Property, Plant and Equipment
A6: As at and for the year ended 30 June 2026
A8: Colour key: YELLOW = 30 June 2026 INK (type amount) BLUE = 30 June 2025 last year audited comparative GREEN = auto formula (do not type)
A10: Particulars | B10: Land & land development | C10: Building & civil construction | D10: Plant & machinery | E10: Laboratory & factory equipment | F10: Furniture & fixtures | G10: Office equipment | H10: Computer & IT equipment | I10: Motor vehicles | J10: Total
A11: A. Cost
A12: Opening balance as at 01 July 2025 (last year audited closing) | J12: =SUM(B12:I12)
A13: Add: Addition during the year (INK) | J13: =SUM(B13:I13)
A14: Add: Transfer from capital work-in-progress (INK) | J14: =SUM(B14:I14)
A15: Less: Disposal / adjustment during the year (INK, enter positive) | J15: =SUM(B15:I15)
A16: Closing balance as at 30 June 2026 | B16: =B12+B13+B14-B15 | C16: =C12+C13+C14-C15 | D16: =D12+D13+D14-D15 | E16: =E12+E13+E14-E15 | F16: =F12+F13+F14-F15 | G16: =G12+G13+G14-G15 | H16: =H12+H13+H14-H15 | I16: =I12+I13+I14-I15 | J16: =SUM(B16:I16)
A18: B. Accumulated depreciation
A19: Opening balance as at 01 July 2025 (last year audited closing) | J19: =SUM(B19:I19)
A20: Add: Charged during the year (INK) | J20: =SUM(B20:I20)
A21: Less: Adjustment on disposal (INK, enter positive) | J21: =SUM(B21:I21)
A22: Closing balance as at 30 June 2026 | B22: =B19+B20-B21 | C22: =C19+C20-C21 | D22: =D19+D20-D21 | E22: =E19+E20-E21 | F22: =F19+F20-F21 | G22: =G19+G20-G21 | H22: =H19+H20-H21 | I22: =I19+I20-I21 | J22: =SUM(B22:I22)
A24: C. Written down value
A25: As at 30 June 2026 (to SOFP Note 4 / current year) | B25: =B16-B22 | C25: =C16-C22 | D25: =D16-D22 | E25: =E16-E22 | F25: =F16-F22 | G25: =G16-G22 | H25: =H16-H22 | I25: =I16-I22 | J25: =J16-J22
A26: As at 30 June 2025 (last year audited WDV) | B26: =B12-B19 | C26: =C12-C19 | D26: =D12-D19 | E26: =E12-E19 | F26: =F12-F19 | G26: =G12-G19 | H26: =H12-H19 | I26: =I12-I19 | J26: =J12-J19
A28: Allocation of depreciation charge for the year (INK — must equal J20)
A29: Charged to cost of sales / factory overhead
A30: Charged to administrative expenses
A31: Charged to selling & distribution expenses
A32: Total charge (must = J20) | I32: =I29+I30+I31
A33: Difference vs PPE charge J20 (must be NIL) | I33: =I32-J20
A35: Accounting rates (disclosure — confirm with client policy)
A36: Class | B36: Typical rate (edit)
A37: Land & land development | B37: Nil
A38: Building & civil construction | B38: 2.5% – 10% (straight line / reducing — confirm)
A39: Plant & machinery | B39: 10% – 20%
A40: Laboratory & factory equipment | B40: 10% – 20%
A41: Furniture & fixtures | B41: 10%
A42: Office equipment | B42: 10% – 15%
A43: Computer & IT equipment | B43: 20% – 30%
A44: Motor vehicles | B44: 20%
A47: Disposal of PPE (INK — optional detail)
A48: Sale proceeds
A49: WDV of assets sold (cost disposed − dep adjusted) | C49: =J15-J21
...

Sheet 13_COGS_Factory
A1: RAHMAN ANIS & CO.
A2: Chartered Accountants
A4: Modern Pharmaceuticals Limited
A5: Annexure B — Cost of sales and factory overhead
A6: For the year ended 30 June 2026
A8: Colour key: YELLOW = 30 June 2026 INK (type amount) BLUE = 30 June 2025 last year audited comparative GREEN = auto formula (do not type)
A9: Particulars | B9: Notes | C9: 30 June 2026 Taka (INK — fill) | D9: 30 June 2025 Taka (Last year audited)
A10: A. Raw and packing materials consumed
A11: Opening stock of raw materials | B11: 9.01
A12: Add: Purchase of raw materials
A13: Raw materials available | C13: =C11+C12 | D13: =D11+D12
A14: Less: Closing stock of raw materials | B14: 9.01
A15: Raw materials consumed | C15: =C13-C14 | D15: =D13-D14
A17: Opening stock of packing materials | B17: 9.02
A18: Add: Purchase of packing materials
A19: Packing materials available | C19: =C17+C18 | D19: =D17+D18
A20: Less: Closing stock of packing materials | B20: 9.02
A21: Packing materials consumed | C21: =C19-C20 | D21: =D19-D20
A23: B. Factory overhead
A24: Factory salaries, wages and overtime
A25: Festival bonus — factory
A26: Provident fund / gratuity — factory
A27: Power, fuel and electricity (factory)
A28: Gas, water and generator
A29: Repairs and maintenance — plant & machinery
A30: Repairs and maintenance — factory building
A31: Consumable stores and spares consumed
A32: Laboratory and quality control expenses
A33: ETP and environmental compliance
A34: Factory rent / rates and taxes
A35: Insurance — factory
A36: Depreciation — factory (link PPE I29) | C36: ='12_PPE_Schedule'!I29
A37: Other factory overhead
A38: Total factory overhead | C38: =SUM(C24:C37) | D38: =SUM(D24:D37)
A40: C. Work-in-process
A41: Opening work-in-process | B41: 9.03
A42: Closing work-in-process | B42: 9.03
A44: Cost of goods manufactured | C44: =C15+C21+C38+C41-C42 | D44: =D15+D21+D38+D41-D42
A46: D. Finished goods
A47: Opening stock of finished goods | B47: 9.04
...

Sheet 14_Admin_Selling
A1: RAHMAN ANIS & CO.
A2: Chartered Accountants
A4: Modern Pharmaceuticals Limited
A5: Annexure C — Administrative and selling & distribution expenses
A6: For the year ended 30 June 2026
A8: Colour key: YELLOW = 30 June 2026 INK (type amount) BLUE = 30 June 2025 last year audited comparative GREEN = auto formula (do not type)
A9: Particulars | B9: Notes | C9: 30 June 2026 Taka (INK — fill) | D9: 30 June 2025 Taka (Last year audited)
A10: A. Administrative expenses
A11: Directors' remuneration
A12: Salaries, wages and allowances — admin
A13: Festival bonus — admin
A14: Provident fund / gratuity — admin
A15: Office rent
A16: Rates, taxes and licence fees (excluding income tax)
A17: Electricity, utilities and office maintenance
A18: Printing, stationery and postage
A19: Telephone, mobile and internet
A20: Travel, conveyance and vehicle running — admin
A21: Repair and maintenance — office
... A29: IT, software and computer maintenance
A30: Depreciation — administrative (link PPE I30) | C30: ='12_PPE_Schedule'!I30
A31: Amortisation of intangible / ROU (admin portion) (INK)
A32: CSR / donation (if any, allowable separately)
A33: Miscellaneous administrative expenses
A34: Total administrative expenses (to SOPL / Note 27) | C34: =SUM(C11:C33) | D34: =SUM(D11:D33)
A36: B. Selling and distribution expenses
A37: Salaries, wages and allowances — sales & distribution
A38: Festival bonus — sales
A39: Provident fund / gratuity — sales
A40: Depot and warehouse rent
A41: Carriage outward / distribution and handling
A42: Promotional expenses, campaign and literature
A43: Physician samples (at cost)
A44: Product registration, DAM and regulatory fees
A45: Travel, conveyance and TA/DA — field force
A46: Vehicle running — sales
A47: Incentive, commission and bonus to field force
... A49: Insurance — goods in transit / depot
A50: Depreciation — selling (link PPE I31) | C50: ='12_PPE_Schedule'!I31
A51: Bad debts / expected credit loss (INK)
...

Sheet 15_Tax_WPPF
A1: RAHMAN ANIS & CO.
A2: Chartered Accountants
A4: Modern Pharmaceuticals Limited
A5: Annexure D — WPPF, current tax and deferred tax workings
A6: For the year ended 30 June 2026
A8: Colour key: YELLOW = 30 June 2026 INK (type amount) BLUE = 30 June 2025 last year audited comparative GREEN = auto formula (do not type)
A9: Particulars | B9: Notes | C9: 30 June 2026 Taka (INK — fill) | D9: 30 June 2025 Taka (Last year audited)
A10: A. Workers' Profit Participation Fund (Bangladesh Labour Act)
A11: Profit before WPPF and tax (auto from SOPL) | C11: =05_SOPL!C19 | D11: =05_SOPL!D19
A12: WPPF @ 5% of profit before WPPF & tax [P × 5/105] (formula) | C12: =IF(C11=0,"",C11*5/105) | D12: =IF(D11=0,"",D11*5/105)
A13: WPPF charged in P&L — override if different (else leave blank; Note 31 uses calc)
A14: WPPF used in statements (override if given, else formula) | C14: =IF(C13="",C12,C13) | D14: =IF(D13="",D12,D13)
A16: B. Current tax (Income Tax Act 2023 — confirm rate with tax file)
A17: Accounting profit before tax (auto from SOPL) | C17: =05_SOPL!C21 | D17: =05_SOPL!D21
A18: Add: Inadmissible expenses / accounting dep (INK)
A19: Less: Admissible deductions / tax depreciation (INK)
A20: Taxable income | C20: =C17+C18-C19 | D20: =D17+D18-D19
A21: Corporate tax rate % (e.g. 20 / 22.5 / 27.5 — INK)
A22: Current tax on taxable income (formula) | C22: =C20*C21 | D22: =D20*D21
A23: Minimum / turnover tax if applicable (INK)
A24: Prior year (over)/under provision (INK)
A25: Current tax expense used in P&L (max of calculated, min tax) + prior | C25: =MAX(C22,C23)+C24 | D25: =MAX(D22,D23)+D24
A27: C. Deferred tax (IAS 12) — simplified temporary difference
A28: Tax base of PPE (INK — tax WDV)
A29: Carrying amount of PPE (auto from PPE schedule) | C29: ='12_PPE_Schedule'!J25 | D29: ='12_PPE_Schedule'!J26
A30: Taxable / (deductible) temporary difference — PPE | C30: =C29-C28 | D30: =D29-D28
A31: Other taxable / (deductible) temporary differences (INK)
A32: Net temporary difference | C32: =C30+C31 | D32: =D30+D31
A33: Deferred tax rate % (INK)
A34: Deferred tax liability / (asset) at year end | C34: =C32*C33 | D34: =D32*D33
A35: Deferred tax expense / (income) for the year | C35: =C34-D34 | D35: 0
A37: D. Provision for income tax — movement (Note 22)
A38: Opening provision (last year audited)
A39: Add: Current tax expense (auto) | C39: =C25 | D39: =D25
A40: Less: Paid / adjusted with AIT during the year (INK)
A41: Closing provision for income tax (to SOFP Note 22) | C41: =C38+C39-C40 | D41: =D38+D39-D40
A43: E. WPPF liability movement (Note 23)
A44: Opening WPPF payable (last year audited)
A45: Add: Contribution for the year (auto) | C45: =C14 | D45: =D14
A46: Less: Paid during the year (INK)
...

Sheet 16_Balance_Check
A1: RAHMAN ANIS & CO.
A2: Chartered Accountants
A4: Modern Pharmaceuticals Limited
A5: Control sheet — balance checks (all differences MUST be NIL before sign-off)
A6: Year ended 30 June 2026
A9: Check | B9: 30 June 2026 | C9: 30 June 2025 | D9: What to do if not NIL
A10: SOFP: Assets − Equity & liabilities | B10: =04_SOFP!C57 | C10: =04_SOFP!D57 | D10: Post missing line or correct note total
A11: SOCIE total equity vs SOFP total equity | B11: =06_SOCIE!F21-04_SOFP!C37 | C11: =06_SOCIE!F14-04_SOFP!D37 | D11: Share capital / RE / premium mismatch vs Notes 14–15
A12: SOCIE share capital vs Note 14 paid-up | B12: =06_SOCIE!B21-'09_Notes_SOFP'!C72 | C12: =06_SOCIE!B14-'09_Notes_SOFP'!D72 | D12: Put paid-up capital in Note 14 AND SOCIE row 10/19
A13: Cash flow closing cash vs SOFP cash | B13: =07_SOCF!C54 | C13: =07_SOCF!D54 | D13: Fill tax paid / capex / loan movement inks on SOCF
A14: PPE dep allocation vs charge | B14: ='12_PPE_Schedule'!I33 | C14: n/a | D14: I29+I30+I31 must equal J20
A15: Inventory note vs COGS closings (RM+PK+WIP+FG) | B15: ='09_Notes_SOFP'!C30+'09_Notes_SOFP'!C31+'09_Notes_SOFP'!C32+'09_Notes_SOFP'!C33-'09_Notes_SOFP'!C38 | C15: ='09_Notes_SOFP'!D30+'09_Notes_SOFP'!D31+'09_Notes_SOFP'!D32+'09_Notes_SOFP'!D33-'09_Notes_SOFP'!D38 | D15: Use same closing stocks in Annexure B and Note 9
A16: PAT in SOPL vs SOCIE current year | B16: =05_SOPL!C23-06_SOCIE!E17 | C16: =05_SOPL!D23-06_SOCIE!E11 | D16: Should be auto-linked; check if SOCIE overwritten
A17: WPPF P&L vs Annexure D | B17: =05_SOPL!C20-'15_Tax_WPPF'!C14 | C17: =05_SOPL!D20-'15_Tax_WPPF'!D14 | D17: Should be auto-linked
A18: Current tax P&L vs Annexure D | B18: ='10_Notes_PL'!C40-'15_Tax_WPPF'!C25 | C18: ='10_Notes_PL'!D40-'15_Tax_WPPF'!D25 | D18: Should be auto-linked
A21: Status | B21: =IF(AND(ABS(B10)<0.5,ABS(B11)<0.5,ABS(B12)<0.5,ABS(B13)<0.5,ABS(B14)<0.5,ABS(B16)<0.5,ABS(B17)<0.5,ABS(B18)<0.5),"READY FOR PARTNER REVIEW","OPEN DIFFERENCES — DO NOT SIGN")
A23: Completion reminder (Bangla)
A24: 2026 YELLOW cells-e current year amount boshan. 2025 BLUE cells-e last year audited figure boshan. Last year PDF ei session-e paowa jay nai — tai BLUE column khali. PDF dile ami BLUE column fill kore updated Excel dite parbo. Green cells formula — overwrite korben na. 16_Balance_Check NIL hole 03_Auditors_Report e date/DVC/partner boshan, then print.
